<?xml version="1.0"?>
<robot xmlns:xacro="http://ros.org/wiki/xacro" name="padlet_robot">
    
    <!-- Definición del parámetro scale con un valor por defecto -->
    <xacro:property name="scale" value="0.001 0.001 0.001"/>
    <material name="light_black">
        <color rgba="0.4 0.4 0.4 1.0"/>
    </material>

    <link name="base_padlet">
        <visual>
            <origin xyz="0.10 0.03 -0.147" rpy="${pi/2} 0 0"/>
            <geometry>
                <mesh filename="package://bot_trevier/meshes/padlet.stl" scale="${scale}"/>
            </geometry>
            <material name='light_black'/>
        </visual>
        <collision>
            <origin xyz="0.10 0.03 -0.147" rpy="${pi/2} 0 0"/>
            <geometry>
                <mesh filename="package://bot_trevier/meshes/padlet.stl" scale="${scale}"/>
            </geometry>
        </collision>
        <xacro:inertial_box mass="2" x="0.5" y="0.25" z="0.15">
            <origin xyz="0 0 0.0" rpy="0 0 0"/>
        </xacro:inertial_box>
    </link>

    <joint name="padlet_joint" type="revolute">
        <parent link="chassis"/>
        <child link="base_padlet"/>
        <origin xyz="0.30 0.15 0.07" rpy="${pi/2} ${pi} ${pi}"/>
        <axis xyz="0.0 0.0 -1.0"/>              
        <limit lower="0.0" upper="${pi/4}" effort="5.0" velocity="1.0"/>
    </joint>

    <gazebo reference="base_padlet">
        <material>Gazebo/Grey</material>
    </gazebo>
    
</robot>
